[2025-05-08T04:16:15.258+0000] {local_task_job_runner.py:123} INFO - ::group::Pre task execution logs
[2025-05-08T04:16:15.270+0000] {taskinstance.py:2603} INFO - Dependencies all met for dep_context=non-requeueable deps ti=<TaskInstance: instagram_videos_scraper_dag.ins_videos_scraper manual__2025-05-08T04:16:07.993695+00:00 [queued]>
[2025-05-08T04:16:15.276+0000] {taskinstance.py:2603} INFO - Dependencies all met for dep_context=requeueable deps ti=<TaskInstance: instagram_videos_scraper_dag.ins_videos_scraper manual__2025-05-08T04:16:07.993695+00:00 [queued]>
[2025-05-08T04:16:15.276+0000] {taskinstance.py:2856} INFO - Starting attempt 1 of 1
[2025-05-08T04:16:15.285+0000] {taskinstance.py:2879} INFO - Executing <Task(_PythonDecoratedOperator): ins_videos_scraper> on 2025-05-08 04:16:07.993695+00:00
[2025-05-08T04:16:15.289+0000] {standard_task_runner.py:72} INFO - Started process 192 to run task
[2025-05-08T04:16:15.290+0000] {standard_task_runner.py:104} INFO - Running: ['airflow', 'tasks', 'run', 'instagram_videos_scraper_dag', 'ins_videos_scraper', 'manual__2025-05-08T04:16:07.993695+00:00', '--job-id', '4937', '--raw', '--subdir', 'DAGS_FOLDER/pipeline.py', '--cfg-path', '/tmp/tmpq_3ieqhj']
[2025-05-08T04:16:15.292+0000] {standard_task_runner.py:105} INFO - Job 4937: Subtask ins_videos_scraper
[2025-05-08T04:16:15.328+0000] {task_command.py:467} INFO - Running <TaskInstance: instagram_videos_scraper_dag.ins_videos_scraper manual__2025-05-08T04:16:07.993695+00:00 [running]> on host 1f91b57718d6
[2025-05-08T04:16:15.396+0000] {taskinstance.py:3122} INFO - Exporting env vars: AIRFLOW_CTX_DAG_OWNER='airflow' AIRFLOW_CTX_DAG_ID='instagram_videos_scraper_dag' AIRFLOW_CTX_TASK_ID='ins_videos_scraper' AIRFLOW_CTX_EXECUTION_DATE='2025-05-08T04:16:07.993695+00:00' AIRFLOW_CTX_TRY_NUMBER='1' AIRFLOW_CTX_DAG_RUN_ID='manual__2025-05-08T04:16:07.993695+00:00'
[2025-05-08T04:16:15.397+0000] {taskinstance.py:731} INFO - ::endgroup::
[2025-05-08T04:16:40.244+0000] {selenium_manager.py:133} WARNING - Exception trying to discover chromedriver version: error sending request for url (https://googlechromelabs.github.io/chrome-for-testing/known-good-versions-with-downloads.json): error trying to connect: dns error: failed to lookup address information: Try again
[2025-05-08T04:16:42.964+0000] {logging_mixin.py:190} INFO - Step 1 of 2 - Loading profile page
[2025-05-08T04:16:42.964+0000] {logging_mixin.py:190} INFO - Extracting videos...
[2025-05-08T04:16:45.795+0000] {logging_mixin.py:190} INFO - Found 50 video tags
[2025-05-08T04:16:46.054+0000] {logging_mixin.py:190} INFO - Extracted 0 video URLs
[2025-05-08T04:16:46.055+0000] {logging_mixin.py:190} INFO -  No data found
[2025-05-08T04:16:46.193+0000] {connectionpool.py:870} WARNING - Retrying (Retry(total=2, connect=None, read=None, redirect=None, status=None)) after connection broken by 'NewConnectionError('<urllib3.connection.HTTPConnection object at 0x7fb073f821d0>: Failed to establish a new connection: [Errno 111] Connection refused')': /session/8f0aa4c258a0e6b7e028d8e5ac4d7fdc
[2025-05-08T04:16:46.193+0000] {connectionpool.py:870} WARNING - Retrying (Retry(total=1, connect=None, read=None, redirect=None, status=None)) after connection broken by 'NewConnectionError('<urllib3.connection.HTTPConnection object at 0x7fb073f81570>: Failed to establish a new connection: [Errno 111] Connection refused')': /session/8f0aa4c258a0e6b7e028d8e5ac4d7fdc
[2025-05-08T04:16:46.194+0000] {connectionpool.py:870} WARNING - Retrying (Retry(total=0, connect=None, read=None, redirect=None, status=None)) after connection broken by 'NewConnectionError('<urllib3.connection.HTTPConnection object at 0x7fb073f81600>: Failed to establish a new connection: [Errno 111] Connection refused')': /session/8f0aa4c258a0e6b7e028d8e5ac4d7fdc
[2025-05-08T04:16:46.195+0000] {logging_mixin.py:190} INFO - Reading URLs from scraped_data/instagram.txt...
[2025-05-08T04:16:46.465+0000] {taskinstance.py:3301} ERROR - Task failed with exception
Traceback (most recent call last):
  File "/home/airflow/.local/lib/python3.10/site-packages/airflow/models/taskinstance.py", line 767, in _execute_task
    result = _execute_callable(context=context, **execute_callable_kwargs)
  File "/home/airflow/.local/lib/python3.10/site-packages/airflow/models/taskinstance.py", line 733, in _execute_callable
    return ExecutionCallableRunner(
  File "/home/airflow/.local/lib/python3.10/site-packages/airflow/utils/operator_helpers.py", line 252, in run
    return self.func(*args, **kwargs)
  File "/home/airflow/.local/lib/python3.10/site-packages/airflow/models/baseoperator.py", line 406, in wrapper
    return func(self, *args, **kwargs)
  File "/home/airflow/.local/lib/python3.10/site-packages/airflow/decorators/base.py", line 266, in execute
    return_value = super().execute(context)
  File "/home/airflow/.local/lib/python3.10/site-packages/airflow/models/baseoperator.py", line 406, in wrapper
    return func(self, *args, **kwargs)
  File "/home/airflow/.local/lib/python3.10/site-packages/airflow/operators/python.py", line 238, in execute
    return_value = self.execute_callable()
  File "/home/airflow/.local/lib/python3.10/site-packages/airflow/operators/python.py", line 256, in execute_callable
    return runner.run(*self.op_args, **self.op_kwargs)
  File "/home/airflow/.local/lib/python3.10/site-packages/airflow/utils/operator_helpers.py", line 252, in run
    return self.func(*args, **kwargs)
  File "/opt/airflow/dags/tasks/insta_scraper.py", line 19, in ins_videos_scraper
    batch_download_from_file(INSTAGRAM_FILE_PATH, download_directory, tiktok=False)
  File "/opt/airflow/dags/utils/downloader.py", line 116, in batch_download_from_file
    with open(file_path, "r") as file:
FileNotFoundError: [Errno 2] No such file or directory: 'scraped_data/instagram.txt'
[2025-05-08T04:16:46.473+0000] {taskinstance.py:1225} INFO - Marking task as FAILED. dag_id=instagram_videos_scraper_dag, task_id=ins_videos_scraper, run_id=manual__2025-05-08T04:16:07.993695+00:00, execution_date=20250508T041607, start_date=20250508T041615, end_date=20250508T041646
[2025-05-08T04:16:46.487+0000] {taskinstance.py:340} INFO - ::group::Post task execution logs
[2025-05-08T04:16:46.488+0000] {standard_task_runner.py:124} ERROR - Failed to execute job 4937 for task ins_videos_scraper ([Errno 2] No such file or directory: 'scraped_data/instagram.txt'; 192)
Traceback (most recent call last):
  File "/home/airflow/.local/lib/python3.10/site-packages/airflow/task/task_runner/standard_task_runner.py", line 117, in _start_by_fork
    ret = args.func(args, dag=self.dag)
  File "/home/airflow/.local/lib/python3.10/site-packages/airflow/cli/cli_config.py", line 49, in command
    return func(*args, **kwargs)
  File "/home/airflow/.local/lib/python3.10/site-packages/airflow/utils/cli.py", line 115, in wrapper
    return f(*args, **kwargs)
  File "/home/airflow/.local/lib/python3.10/site-packages/airflow/cli/commands/task_command.py", line 483, in task_run
    task_return_code = _run_task_by_selected_method(args, _dag, ti)
  File "/home/airflow/.local/lib/python3.10/site-packages/airflow/cli/commands/task_command.py", line 256, in _run_task_by_selected_method
    return _run_raw_task(args, ti)
  File "/home/airflow/.local/lib/python3.10/site-packages/airflow/cli/commands/task_command.py", line 341, in _run_raw_task
    return ti._run_raw_task(
  File "/home/airflow/.local/lib/python3.10/site-packages/airflow/utils/session.py", line 97, in wrapper
    return func(*args, session=session, **kwargs)
  File "/home/airflow/.local/lib/python3.10/site-packages/airflow/models/taskinstance.py", line 2995, in _run_raw_task
    return _run_raw_task(
  File "/home/airflow/.local/lib/python3.10/site-packages/airflow/models/taskinstance.py", line 273, in _run_raw_task
    TaskInstance._execute_task_with_callbacks(
  File "/home/airflow/.local/lib/python3.10/site-packages/airflow/models/taskinstance.py", line 3149, in _execute_task_with_callbacks
    result = self._execute_task(context, task_orig)
  File "/home/airflow/.local/lib/python3.10/site-packages/airflow/models/taskinstance.py", line 3173, in _execute_task
    return _execute_task(self, context, task_orig)
  File "/home/airflow/.local/lib/python3.10/site-packages/airflow/models/taskinstance.py", line 767, in _execute_task
    result = _execute_callable(context=context, **execute_callable_kwargs)
  File "/home/airflow/.local/lib/python3.10/site-packages/airflow/models/taskinstance.py", line 733, in _execute_callable
    return ExecutionCallableRunner(
  File "/home/airflow/.local/lib/python3.10/site-packages/airflow/utils/operator_helpers.py", line 252, in run
    return self.func(*args, **kwargs)
  File "/home/airflow/.local/lib/python3.10/site-packages/airflow/models/baseoperator.py", line 406, in wrapper
    return func(self, *args, **kwargs)
  File "/home/airflow/.local/lib/python3.10/site-packages/airflow/decorators/base.py", line 266, in execute
    return_value = super().execute(context)
  File "/home/airflow/.local/lib/python3.10/site-packages/airflow/models/baseoperator.py", line 406, in wrapper
    return func(self, *args, **kwargs)
  File "/home/airflow/.local/lib/python3.10/site-packages/airflow/operators/python.py", line 238, in execute
    return_value = self.execute_callable()
  File "/home/airflow/.local/lib/python3.10/site-packages/airflow/operators/python.py", line 256, in execute_callable
    return runner.run(*self.op_args, **self.op_kwargs)
  File "/home/airflow/.local/lib/python3.10/site-packages/airflow/utils/operator_helpers.py", line 252, in run
    return self.func(*args, **kwargs)
  File "/opt/airflow/dags/tasks/insta_scraper.py", line 19, in ins_videos_scraper
    batch_download_from_file(INSTAGRAM_FILE_PATH, download_directory, tiktok=False)
  File "/opt/airflow/dags/utils/downloader.py", line 116, in batch_download_from_file
    with open(file_path, "r") as file:
FileNotFoundError: [Errno 2] No such file or directory: 'scraped_data/instagram.txt'
[2025-05-08T04:16:46.507+0000] {local_task_job_runner.py:261} INFO - Task exited with return code 1
[2025-05-08T04:16:46.520+0000] {taskinstance.py:3891} INFO - 0 downstream tasks scheduled from follow-on schedule check
[2025-05-08T04:16:46.522+0000] {local_task_job_runner.py:240} INFO - ::endgroup::
