[2025-05-07T10:45:43.649+0000] {local_task_job_runner.py:123} INFO - ::group::Pre task execution logs
[2025-05-07T10:45:43.661+0000] {taskinstance.py:2603} INFO - Dependencies all met for dep_context=non-requeueable deps ti=<TaskInstance: instagram_videos_scraper_dag.ins_videos_scraper manual__2025-05-07T10:45:35.424648+00:00 [queued]>
[2025-05-07T10:45:43.666+0000] {taskinstance.py:2603} INFO - Dependencies all met for dep_context=requeueable deps ti=<TaskInstance: instagram_videos_scraper_dag.ins_videos_scraper manual__2025-05-07T10:45:35.424648+00:00 [queued]>
[2025-05-07T10:45:43.667+0000] {taskinstance.py:2856} INFO - Starting attempt 1 of 1
[2025-05-07T10:45:43.674+0000] {taskinstance.py:2879} INFO - Executing <Task(_PythonDecoratedOperator): ins_videos_scraper> on 2025-05-07 10:45:35.424648+00:00
[2025-05-07T10:45:43.678+0000] {standard_task_runner.py:72} INFO - Started process 3941 to run task
[2025-05-07T10:45:43.682+0000] {standard_task_runner.py:104} INFO - Running: ['airflow', 'tasks', 'run', 'instagram_videos_scraper_dag', 'ins_videos_scraper', 'manual__2025-05-07T10:45:35.424648+00:00', '--job-id', '4914', '--raw', '--subdir', 'DAGS_FOLDER/pipeline.py', '--cfg-path', '/tmp/tmp1rjzskc5']
[2025-05-07T10:45:43.684+0000] {standard_task_runner.py:105} INFO - Job 4914: Subtask ins_videos_scraper
[2025-05-07T10:45:43.719+0000] {task_command.py:467} INFO - Running <TaskInstance: instagram_videos_scraper_dag.ins_videos_scraper manual__2025-05-07T10:45:35.424648+00:00 [running]> on host 83f5c4ce7f9b
[2025-05-07T10:45:43.783+0000] {taskinstance.py:3122} INFO - Exporting env vars: AIRFLOW_CTX_DAG_OWNER='airflow' AIRFLOW_CTX_DAG_ID='instagram_videos_scraper_dag' AIRFLOW_CTX_TASK_ID='ins_videos_scraper' AIRFLOW_CTX_EXECUTION_DATE='2025-05-07T10:45:35.424648+00:00' AIRFLOW_CTX_TRY_NUMBER='1' AIRFLOW_CTX_DAG_RUN_ID='manual__2025-05-07T10:45:35.424648+00:00'
[2025-05-07T10:45:43.784+0000] {taskinstance.py:731} INFO - ::endgroup::
[2025-05-07T10:45:43.873+0000] {selenium_manager.py:133} WARNING - The chromedriver version (136.0.7103.59) detected in PATH at /usr/bin/chromedriver might not be compatible with the detected chrome version (136.0.7103.92); currently, chromedriver 136.0.7103.92 is recommended for chrome 136.*, so it is advised to delete the driver in PATH and retry
[2025-05-07T10:45:44.650+0000] {taskinstance.py:3301} ERROR - Task failed with exception
Traceback (most recent call last):
  File "/home/airflow/.local/lib/python3.10/site-packages/airflow/models/taskinstance.py", line 767, in _execute_task
    result = _execute_callable(context=context, **execute_callable_kwargs)
  File "/home/airflow/.local/lib/python3.10/site-packages/airflow/models/taskinstance.py", line 733, in _execute_callable
    return ExecutionCallableRunner(
  File "/home/airflow/.local/lib/python3.10/site-packages/airflow/utils/operator_helpers.py", line 252, in run
    return self.func(*args, **kwargs)
  File "/home/airflow/.local/lib/python3.10/site-packages/airflow/models/baseoperator.py", line 406, in wrapper
    return func(self, *args, **kwargs)
  File "/home/airflow/.local/lib/python3.10/site-packages/airflow/decorators/base.py", line 266, in execute
    return_value = super().execute(context)
  File "/home/airflow/.local/lib/python3.10/site-packages/airflow/models/baseoperator.py", line 406, in wrapper
    return func(self, *args, **kwargs)
  File "/home/airflow/.local/lib/python3.10/site-packages/airflow/operators/python.py", line 238, in execute
    return_value = self.execute_callable()
  File "/home/airflow/.local/lib/python3.10/site-packages/airflow/operators/python.py", line 256, in execute_callable
    return runner.run(*self.op_args, **self.op_kwargs)
  File "/home/airflow/.local/lib/python3.10/site-packages/airflow/utils/operator_helpers.py", line 252, in run
    return self.func(*args, **kwargs)
  File "/opt/airflow/dags/tasks/insta_scraper.py", line 17, in ins_videos_scraper
    scraper = ProfileScraper(id)
  File "/opt/airflow/dags/utils/instagram_profile.py", line 16, in __init__
    super().__init__(
  File "/opt/airflow/dags/utils/instagram_base.py", line 26, in __init__
    self._driver = webdriver.Chrome(options=options)
  File "/home/airflow/.local/lib/python3.10/site-packages/selenium/webdriver/chrome/webdriver.py", line 45, in __init__
    super().__init__(
  File "/home/airflow/.local/lib/python3.10/site-packages/selenium/webdriver/chromium/webdriver.py", line 56, in __init__
    super().__init__(
  File "/home/airflow/.local/lib/python3.10/site-packages/selenium/webdriver/remote/webdriver.py", line 206, in __init__
    self.start_session(capabilities)
  File "/home/airflow/.local/lib/python3.10/site-packages/selenium/webdriver/remote/webdriver.py", line 290, in start_session
    response = self.execute(Command.NEW_SESSION, caps)["value"]
  File "/home/airflow/.local/lib/python3.10/site-packages/selenium/webdriver/remote/webdriver.py", line 345, in execute
    self.error_handler.check_response(response)
  File "/home/airflow/.local/lib/python3.10/site-packages/selenium/webdriver/remote/errorhandler.py", line 229, in check_response
    raise exception_class(message, screen, stacktrace)
selenium.common.exceptions.SessionNotCreatedException: Message: session not created: probably user data directory is already in use, please specify a unique value for --user-data-dir argument, or don't use --user-data-dir
Stacktrace:
#0 0x559fb1817a8e <unknown>
#1 0x559fb12d4b0b <unknown>
#2 0x559fb130b4ea <unknown>
#3 0x559fb1306aef <unknown>
#4 0x559fb135ab18 <unknown>
#5 0x559fb13489b3 <unknown>
#6 0x559fb1312c59 <unknown>
#7 0x559fb1313a08 <unknown>
#8 0x559fb17e440a <unknown>
#9 0x559fb17e785e <unknown>
#10 0x559fb17e7308 <unknown>
#11 0x559fb17e7ce5 <unknown>
#12 0x559fb17cdb7b <unknown>
#13 0x559fb17e8050 <unknown>
#14 0x559fb17b6ae9 <unknown>
#15 0x559fb1806df5 <unknown>
#16 0x559fb1806fdb <unknown>
#17 0x559fb1816c05 <unknown>
#18 0x7f49af6fb134 <unknown>

[2025-05-07T10:45:44.667+0000] {taskinstance.py:1225} INFO - Marking task as FAILED. dag_id=instagram_videos_scraper_dag, task_id=ins_videos_scraper, run_id=manual__2025-05-07T10:45:35.424648+00:00, execution_date=20250507T104535, start_date=20250507T104543, end_date=20250507T104544
[2025-05-07T10:45:44.677+0000] {taskinstance.py:340} INFO - ::group::Post task execution logs
[2025-05-07T10:45:44.677+0000] {standard_task_runner.py:124} ERROR - Failed to execute job 4914 for task ins_videos_scraper (Message: session not created: probably user data directory is already in use, please specify a unique value for --user-data-dir argument, or don't use --user-data-dir
Stacktrace:
#0 0x559fb1817a8e <unknown>
#1 0x559fb12d4b0b <unknown>
#2 0x559fb130b4ea <unknown>
#3 0x559fb1306aef <unknown>
#4 0x559fb135ab18 <unknown>
#5 0x559fb13489b3 <unknown>
#6 0x559fb1312c59 <unknown>
#7 0x559fb1313a08 <unknown>
#8 0x559fb17e440a <unknown>
#9 0x559fb17e785e <unknown>
#10 0x559fb17e7308 <unknown>
#11 0x559fb17e7ce5 <unknown>
#12 0x559fb17cdb7b <unknown>
#13 0x559fb17e8050 <unknown>
#14 0x559fb17b6ae9 <unknown>
#15 0x559fb1806df5 <unknown>
#16 0x559fb1806fdb <unknown>
#17 0x559fb1816c05 <unknown>
#18 0x7f49af6fb134 <unknown>
; 3941)
Traceback (most recent call last):
  File "/home/airflow/.local/lib/python3.10/site-packages/airflow/task/task_runner/standard_task_runner.py", line 117, in _start_by_fork
    ret = args.func(args, dag=self.dag)
  File "/home/airflow/.local/lib/python3.10/site-packages/airflow/cli/cli_config.py", line 49, in command
    return func(*args, **kwargs)
  File "/home/airflow/.local/lib/python3.10/site-packages/airflow/utils/cli.py", line 115, in wrapper
    return f(*args, **kwargs)
  File "/home/airflow/.local/lib/python3.10/site-packages/airflow/cli/commands/task_command.py", line 483, in task_run
    task_return_code = _run_task_by_selected_method(args, _dag, ti)
  File "/home/airflow/.local/lib/python3.10/site-packages/airflow/cli/commands/task_command.py", line 256, in _run_task_by_selected_method
    return _run_raw_task(args, ti)
  File "/home/airflow/.local/lib/python3.10/site-packages/airflow/cli/commands/task_command.py", line 341, in _run_raw_task
    return ti._run_raw_task(
  File "/home/airflow/.local/lib/python3.10/site-packages/airflow/utils/session.py", line 97, in wrapper
    return func(*args, session=session, **kwargs)
  File "/home/airflow/.local/lib/python3.10/site-packages/airflow/models/taskinstance.py", line 2995, in _run_raw_task
    return _run_raw_task(
  File "/home/airflow/.local/lib/python3.10/site-packages/airflow/models/taskinstance.py", line 273, in _run_raw_task
    TaskInstance._execute_task_with_callbacks(
  File "/home/airflow/.local/lib/python3.10/site-packages/airflow/models/taskinstance.py", line 3149, in _execute_task_with_callbacks
    result = self._execute_task(context, task_orig)
  File "/home/airflow/.local/lib/python3.10/site-packages/airflow/models/taskinstance.py", line 3173, in _execute_task
    return _execute_task(self, context, task_orig)
  File "/home/airflow/.local/lib/python3.10/site-packages/airflow/models/taskinstance.py", line 767, in _execute_task
    result = _execute_callable(context=context, **execute_callable_kwargs)
  File "/home/airflow/.local/lib/python3.10/site-packages/airflow/models/taskinstance.py", line 733, in _execute_callable
    return ExecutionCallableRunner(
  File "/home/airflow/.local/lib/python3.10/site-packages/airflow/utils/operator_helpers.py", line 252, in run
    return self.func(*args, **kwargs)
  File "/home/airflow/.local/lib/python3.10/site-packages/airflow/models/baseoperator.py", line 406, in wrapper
    return func(self, *args, **kwargs)
  File "/home/airflow/.local/lib/python3.10/site-packages/airflow/decorators/base.py", line 266, in execute
    return_value = super().execute(context)
  File "/home/airflow/.local/lib/python3.10/site-packages/airflow/models/baseoperator.py", line 406, in wrapper
    return func(self, *args, **kwargs)
  File "/home/airflow/.local/lib/python3.10/site-packages/airflow/operators/python.py", line 238, in execute
    return_value = self.execute_callable()
  File "/home/airflow/.local/lib/python3.10/site-packages/airflow/operators/python.py", line 256, in execute_callable
    return runner.run(*self.op_args, **self.op_kwargs)
  File "/home/airflow/.local/lib/python3.10/site-packages/airflow/utils/operator_helpers.py", line 252, in run
    return self.func(*args, **kwargs)
  File "/opt/airflow/dags/tasks/insta_scraper.py", line 17, in ins_videos_scraper
    scraper = ProfileScraper(id)
  File "/opt/airflow/dags/utils/instagram_profile.py", line 16, in __init__
    super().__init__(
  File "/opt/airflow/dags/utils/instagram_base.py", line 26, in __init__
    self._driver = webdriver.Chrome(options=options)
  File "/home/airflow/.local/lib/python3.10/site-packages/selenium/webdriver/chrome/webdriver.py", line 45, in __init__
    super().__init__(
  File "/home/airflow/.local/lib/python3.10/site-packages/selenium/webdriver/chromium/webdriver.py", line 56, in __init__
    super().__init__(
  File "/home/airflow/.local/lib/python3.10/site-packages/selenium/webdriver/remote/webdriver.py", line 206, in __init__
    self.start_session(capabilities)
  File "/home/airflow/.local/lib/python3.10/site-packages/selenium/webdriver/remote/webdriver.py", line 290, in start_session
    response = self.execute(Command.NEW_SESSION, caps)["value"]
  File "/home/airflow/.local/lib/python3.10/site-packages/selenium/webdriver/remote/webdriver.py", line 345, in execute
    self.error_handler.check_response(response)
  File "/home/airflow/.local/lib/python3.10/site-packages/selenium/webdriver/remote/errorhandler.py", line 229, in check_response
    raise exception_class(message, screen, stacktrace)
selenium.common.exceptions.SessionNotCreatedException: Message: session not created: probably user data directory is already in use, please specify a unique value for --user-data-dir argument, or don't use --user-data-dir
Stacktrace:
#0 0x559fb1817a8e <unknown>
#1 0x559fb12d4b0b <unknown>
#2 0x559fb130b4ea <unknown>
#3 0x559fb1306aef <unknown>
#4 0x559fb135ab18 <unknown>
#5 0x559fb13489b3 <unknown>
#6 0x559fb1312c59 <unknown>
#7 0x559fb1313a08 <unknown>
#8 0x559fb17e440a <unknown>
#9 0x559fb17e785e <unknown>
#10 0x559fb17e7308 <unknown>
#11 0x559fb17e7ce5 <unknown>
#12 0x559fb17cdb7b <unknown>
#13 0x559fb17e8050 <unknown>
#14 0x559fb17b6ae9 <unknown>
#15 0x559fb1806df5 <unknown>
#16 0x559fb1806fdb <unknown>
#17 0x559fb1816c05 <unknown>
#18 0x7f49af6fb134 <unknown>

[2025-05-07T10:45:44.697+0000] {local_task_job_runner.py:261} INFO - Task exited with return code 1
[2025-05-07T10:45:44.709+0000] {taskinstance.py:3891} INFO - 0 downstream tasks scheduled from follow-on schedule check
[2025-05-07T10:45:44.711+0000] {local_task_job_runner.py:240} INFO - ::endgroup::
