[2025-05-05T02:31:36.474+0000] {local_task_job_runner.py:123} INFO - ::group::Pre task execution logs
[2025-05-05T02:31:36.499+0000] {taskinstance.py:2603} INFO - Dependencies all met for dep_context=non-requeueable deps ti=<TaskInstance: process_employees.get_data scheduled__2025-04-29T00:00:00+00:00 [queued]>
[2025-05-05T02:31:36.512+0000] {taskinstance.py:2603} INFO - Dependencies all met for dep_context=requeueable deps ti=<TaskInstance: process_employees.get_data scheduled__2025-04-29T00:00:00+00:00 [queued]>
[2025-05-05T02:31:36.512+0000] {taskinstance.py:2856} INFO - Starting attempt 1 of 1
[2025-05-05T02:31:36.528+0000] {taskinstance.py:2879} INFO - Executing <Task(_PythonDecoratedOperator): get_data> on 2025-04-29 00:00:00+00:00
[2025-05-05T02:31:36.533+0000] {standard_task_runner.py:72} INFO - Started process 129 to run task
[2025-05-05T02:31:36.537+0000] {standard_task_runner.py:104} INFO - Running: ['airflow', 'tasks', 'run', 'process_employees', 'get_data', 'scheduled__2025-04-29T00:00:00+00:00', '--job-id', '2480', '--raw', '--subdir', 'DAGS_FOLDER/tuts/simple_data_pipeline.py', '--cfg-path', '/tmp/tmpekuknjvh']
[2025-05-05T02:31:36.538+0000] {standard_task_runner.py:105} INFO - Job 2480: Subtask get_data
[2025-05-05T02:31:36.609+0000] {task_command.py:467} INFO - Running <TaskInstance: process_employees.get_data scheduled__2025-04-29T00:00:00+00:00 [running]> on host 2c7afa36055b
[2025-05-05T02:31:36.709+0000] {taskinstance.py:3122} INFO - Exporting env vars: AIRFLOW_CTX_DAG_OWNER='airflow' AIRFLOW_CTX_DAG_ID='process_employees' AIRFLOW_CTX_TASK_ID='get_data' AIRFLOW_CTX_EXECUTION_DATE='2025-04-29T00:00:00+00:00' AIRFLOW_CTX_TRY_NUMBER='1' AIRFLOW_CTX_DAG_RUN_ID='scheduled__2025-04-29T00:00:00+00:00'
[2025-05-05T02:31:36.710+0000] {taskinstance.py:731} INFO - ::endgroup::
[2025-05-05T02:31:37.279+0000] {base.py:84} INFO - Retrieving connection 'tutorial_pg_conn'
[2025-05-05T02:31:37.284+0000] {taskinstance.py:3301} ERROR - Task failed with exception
Traceback (most recent call last):
  File "/home/airflow/.local/lib/python3.10/site-packages/airflow/models/taskinstance.py", line 767, in _execute_task
    result = _execute_callable(context=context, **execute_callable_kwargs)
  File "/home/airflow/.local/lib/python3.10/site-packages/airflow/models/taskinstance.py", line 733, in _execute_callable
    return ExecutionCallableRunner(
  File "/home/airflow/.local/lib/python3.10/site-packages/airflow/utils/operator_helpers.py", line 252, in run
    return self.func(*args, **kwargs)
  File "/home/airflow/.local/lib/python3.10/site-packages/airflow/models/baseoperator.py", line 406, in wrapper
    return func(self, *args, **kwargs)
  File "/home/airflow/.local/lib/python3.10/site-packages/airflow/decorators/base.py", line 266, in execute
    return_value = super().execute(context)
  File "/home/airflow/.local/lib/python3.10/site-packages/airflow/models/baseoperator.py", line 406, in wrapper
    return func(self, *args, **kwargs)
  File "/home/airflow/.local/lib/python3.10/site-packages/airflow/operators/python.py", line 238, in execute
    return_value = self.execute_callable()
  File "/home/airflow/.local/lib/python3.10/site-packages/airflow/operators/python.py", line 256, in execute_callable
    return runner.run(*self.op_args, **self.op_kwargs)
  File "/home/airflow/.local/lib/python3.10/site-packages/airflow/utils/operator_helpers.py", line 252, in run
    return self.func(*args, **kwargs)
  File "/opt/airflow/dags/tuts/simple_data_pipeline.py", line 63, in get_data
    cur.copy_expert(
psycopg2.errors.UniqueViolation: duplicate key value violates unique constraint "employees_temp_pkey"
DETAIL:  Key ("Serial Number")=(2) already exists.
CONTEXT:  COPY employees_temp, line 2

[2025-05-05T02:31:37.295+0000] {taskinstance.py:1225} INFO - Marking task as FAILED. dag_id=process_employees, task_id=get_data, run_id=scheduled__2025-04-29T00:00:00+00:00, execution_date=20250429T000000, start_date=20250505T023136, end_date=20250505T023137
[2025-05-05T02:31:37.304+0000] {taskinstance.py:340} INFO - ::group::Post task execution logs
[2025-05-05T02:31:37.304+0000] {standard_task_runner.py:124} ERROR - Failed to execute job 2480 for task get_data (duplicate key value violates unique constraint "employees_temp_pkey"
DETAIL:  Key ("Serial Number")=(2) already exists.
CONTEXT:  COPY employees_temp, line 2
; 129)
Traceback (most recent call last):
  File "/home/airflow/.local/lib/python3.10/site-packages/airflow/task/task_runner/standard_task_runner.py", line 117, in _start_by_fork
    ret = args.func(args, dag=self.dag)
  File "/home/airflow/.local/lib/python3.10/site-packages/airflow/cli/cli_config.py", line 49, in command
    return func(*args, **kwargs)
  File "/home/airflow/.local/lib/python3.10/site-packages/airflow/utils/cli.py", line 115, in wrapper
    return f(*args, **kwargs)
  File "/home/airflow/.local/lib/python3.10/site-packages/airflow/cli/commands/task_command.py", line 483, in task_run
    task_return_code = _run_task_by_selected_method(args, _dag, ti)
  File "/home/airflow/.local/lib/python3.10/site-packages/airflow/cli/commands/task_command.py", line 256, in _run_task_by_selected_method
    return _run_raw_task(args, ti)
  File "/home/airflow/.local/lib/python3.10/site-packages/airflow/cli/commands/task_command.py", line 341, in _run_raw_task
    return ti._run_raw_task(
  File "/home/airflow/.local/lib/python3.10/site-packages/airflow/utils/session.py", line 97, in wrapper
    return func(*args, session=session, **kwargs)
  File "/home/airflow/.local/lib/python3.10/site-packages/airflow/models/taskinstance.py", line 2995, in _run_raw_task
    return _run_raw_task(
  File "/home/airflow/.local/lib/python3.10/site-packages/airflow/models/taskinstance.py", line 273, in _run_raw_task
    TaskInstance._execute_task_with_callbacks(
  File "/home/airflow/.local/lib/python3.10/site-packages/airflow/models/taskinstance.py", line 3149, in _execute_task_with_callbacks
    result = self._execute_task(context, task_orig)
  File "/home/airflow/.local/lib/python3.10/site-packages/airflow/models/taskinstance.py", line 3173, in _execute_task
    return _execute_task(self, context, task_orig)
  File "/home/airflow/.local/lib/python3.10/site-packages/airflow/models/taskinstance.py", line 767, in _execute_task
    result = _execute_callable(context=context, **execute_callable_kwargs)
  File "/home/airflow/.local/lib/python3.10/site-packages/airflow/models/taskinstance.py", line 733, in _execute_callable
    return ExecutionCallableRunner(
  File "/home/airflow/.local/lib/python3.10/site-packages/airflow/utils/operator_helpers.py", line 252, in run
    return self.func(*args, **kwargs)
  File "/home/airflow/.local/lib/python3.10/site-packages/airflow/models/baseoperator.py", line 406, in wrapper
    return func(self, *args, **kwargs)
  File "/home/airflow/.local/lib/python3.10/site-packages/airflow/decorators/base.py", line 266, in execute
    return_value = super().execute(context)
  File "/home/airflow/.local/lib/python3.10/site-packages/airflow/models/baseoperator.py", line 406, in wrapper
    return func(self, *args, **kwargs)
  File "/home/airflow/.local/lib/python3.10/site-packages/airflow/operators/python.py", line 238, in execute
    return_value = self.execute_callable()
  File "/home/airflow/.local/lib/python3.10/site-packages/airflow/operators/python.py", line 256, in execute_callable
    return runner.run(*self.op_args, **self.op_kwargs)
  File "/home/airflow/.local/lib/python3.10/site-packages/airflow/utils/operator_helpers.py", line 252, in run
    return self.func(*args, **kwargs)
  File "/opt/airflow/dags/tuts/simple_data_pipeline.py", line 63, in get_data
    cur.copy_expert(
psycopg2.errors.UniqueViolation: duplicate key value violates unique constraint "employees_temp_pkey"
DETAIL:  Key ("Serial Number")=(2) already exists.
CONTEXT:  COPY employees_temp, line 2

[2025-05-05T02:31:37.324+0000] {local_task_job_runner.py:261} INFO - Task exited with return code 1
[2025-05-05T02:31:37.339+0000] {taskinstance.py:3891} INFO - 0 downstream tasks scheduled from follow-on schedule check
[2025-05-05T02:31:37.341+0000] {local_task_job_runner.py:240} INFO - ::endgroup::
